<?xml version="1.0"?>
<robot name="five_dof_arm">
  <!-- Base link -->
  <link name="base_link">
    <visual>
      <geometry>
        <cylinder radius="0.15" length="2.0"/>
      </geometry>
      <material name="gray">
        <color rgba="0.7 0.7 0.7 1.0"/>
      </material>
    </visual>
    <collision>
      <geometry>
        <cylinder radius="0.15" length="2.0"/>
      </geometry>
    </collision>
    <inertial>
      <mass value="10.0"/>
      <inertia ixx="0.4" ixy="0" ixz="0" iyy="0.4" iyz="0" izz="0.4"/>
    </inertial>
  </link>

  <!-- Shoulder link -->
  <link name="shoulder_link">
    <visual>
      <origin xyz="0 0 0.025" rpy="0 0 0"/>
      <geometry>
        <box size="0.05 0.05 0.05"/>
      </geometry>
      <material name="gray">
        <color rgba="0.7 0.7 0.7 1.0"/>
      </material>
    </visual>
    <collision>
      <origin xyz="0 0 0.025" rpy="0 0 0"/>
      <geometry>
        <box size="0.05 0.05 0.05"/>
      </geometry>
    </collision>
    <inertial>
      <origin xyz="0 0 0.025" rpy="0 0 0"/>
      <mass value="0.8"/>
      <inertia ixx="0.008" ixy="0" ixz="0" iyy="0.008" iyz="0" izz="0.008"/>
    </inertial>
  </link>
  
  <!-- Joint 1: Base to Shoulder -->
  <joint name="joint1" type="revolute">
    <parent link="base_link"/>
    <child link="shoulder_link"/>
    <origin xyz="0 0 1.0" rpy="0 0 0"/>
    <axis xyz="0 0 1"/>
    <limit lower="-3.14" upper="3.14" effort="1000" velocity="1.0"/>
    <dynamics damping="50.0" friction="10.0"/>
  </joint>

  <!-- Upper Arm link -->
  <link name="upper_arm_link">
    <visual>
      <origin xyz="0 0 0.215" rpy="0 0 0"/>
      <geometry>
        <cylinder radius="0.02" length="0.43"/>
      </geometry>
      <material name="white">
        <color rgba="1.0 1.0 1.0 1.0"/>
      </material>
    </visual>
    <collision>
      <origin xyz="0 0 0.215" rpy="0 0 0"/>
      <geometry>
        <cylinder radius="0.02" length="0.43"/>
      </geometry>
    </collision>
    <inertial>
      <origin xyz="0 0 0.215" rpy="0 0 0"/>
      <mass value="0.5"/>
      <inertia ixx="0.005" ixy="0" ixz="0" iyy="0.005" iyz="0" izz="0.001"/>
    </inertial>
  </link>
  
  <!-- Joint 2: Shoulder to Upper Arm -->
  <joint name="joint2" type="revolute">
    <parent link="shoulder_link"/>
    <child link="upper_arm_link"/>
    <origin xyz="0 0 0.05" rpy="0 0 0"/>
    <axis xyz="0 1 0"/>
    <limit lower="-0.34" upper="1.57" effort="100" velocity="1.0"/>
    <dynamics damping="50.0" friction="10.0"/>
  </joint>

  <!-- Elbow link -->
  <link name="elbow_link">
    <visual>
      <origin xyz="0 0 0.2" rpy="0 0 0"/>
      <geometry>
        <box size="0.03 0.03 0.4"/>
      </geometry>
      <material name="gray">
        <color rgba="0.7 0.7 0.7 1.0"/>
      </material>
    </visual>
    <collision>
      <origin xyz="0 0 0.2" rpy="0 0 0"/>
      <geometry>
        <box size="0.03 0.03 0.4"/>
      </geometry>
    </collision>
    <inertial>
      <origin xyz="0 0 0.2" rpy="0 0 0"/>
      <mass value="0.4"/>
      <inertia ixx="0.002" ixy="0" ixz="0" iyy="0.002" iyz="0" izz="0.002"/>
    </inertial>
  </link>
  
  <!-- Joint 3: Upper Arm to Elbow -->
  <joint name="joint3" type="revolute">
    <parent link="upper_arm_link"/>
    <child link="elbow_link"/>
    <origin xyz="0 0 0.43" rpy="0 0 0"/>
    <axis xyz="0 1 0"/>
    <limit lower="-1.74" upper="1.74" effort="100" velocity="1.0"/>
    <dynamics damping="50.0" friction="10.0"/>
  </joint>

  <!-- Forearm link -->
  <link name="forearm_link">
    <visual>
      <origin xyz="0 0 0.018" rpy="0 0 0"/>
      <geometry>
        <cylinder radius="0.02" length="0.036"/>
      </geometry>
      <material name="white">
        <color rgba="1.0 1.0 1.0 1.0"/>
      </material>
    </visual>
    <collision>
      <origin xyz="0 0 0.018" rpy="0 0 0"/>
      <geometry>
        <cylinder radius="0.02" length="0.036"/>
      </geometry>
    </collision>
    <inertial>
      <origin xyz="0 0 0.018" rpy="0 0 0"/>
      <mass value="0.3"/>
      <inertia ixx="0.001" ixy="0" ixz="0" iyy="0.001" iyz="0" izz="0.0003"/>
    </inertial>
  </link>
  
  <!-- Joint 4: Elbow to Forearm -->
  <joint name="joint4" type="revolute">
    <parent link="elbow_link"/>
    <child link="forearm_link"/>
    <origin xyz="0 0 0.4" rpy="0 0 0"/>
    <axis xyz="0 0 1"/>
    <limit lower="-3.14" upper="3.14" effort="500" velocity="2.0"/>
    <dynamics damping="5.0" friction="0.5"/>
  </joint>

  <!-- End Effector link -->
  <link name="end_effector_link">
    <visual>
      <origin xyz="0 0 0.035" rpy="0 0 0"/>
      <geometry>
        <box size="0.03 0.05 0.07"/>
      </geometry>
      <material name="dark">
        <color rgba="0.2 0.2 0.2 1.0"/>
      </material>
    </visual>
    <collision>
      <origin xyz="0 0 0.035" rpy="0 0 0"/>
      <geometry>
        <box size="0.03 0.05 0.07"/>
      </geometry>
    </collision>
    <inertial>
      <origin xyz="0 0 0.035" rpy="0 0 0"/>
      <mass value="0.2"/>
      <inertia ixx="0.0002" ixy="0" ixz="0" iyy="0.0002" iyz="0" izz="0.0002"/>
    </inertial>
  </link>
  
  <!-- Joint 5: Forearm to End Effector -->
  <joint name="joint5" type="revolute">
    <parent link="forearm_link"/>
    <child link="end_effector_link"/>
    <origin xyz="0 0 0.036" rpy="0 0 0"/>
    <axis xyz="0 1 0"/>
    <limit lower="-1.27" upper="1.27" effort="200" velocity="1.0"/>
    <dynamics damping="15.0" friction="2.0"/>
  </joint>

  <!-- Add transmission elements for controllers -->
  <transmission name="tran1">
    <type>transmission_interface/SimpleTransmission</type>
    <joint name="joint1">
      <hardwareInterface>hardware_interface/PositionJointInterface</hardwareInterface>
    </joint>
    <actuator name="motor1">
      <hardwareInterface>hardware_interface/PositionJointInterface</hardwareInterface>
      <mechanicalReduction>1</mechanicalReduction>
    </actuator>
  </transmission>

  <transmission name="tran2">
    <type>transmission_interface/SimpleTransmission</type>
    <joint name="joint2">
      <hardwareInterface>hardware_interface/PositionJointInterface</hardwareInterface>
    </joint>
    <actuator name="motor2">
      <hardwareInterface>hardware_interface/PositionJointInterface</hardwareInterface>
      <mechanicalReduction>1</mechanicalReduction>
    </actuator>
  </transmission>

  <transmission name="tran3">
    <type>transmission_interface/SimpleTransmission</type>
    <joint name="joint3">
      <hardwareInterface>hardware_interface/PositionJointInterface</hardwareInterface>
    </joint>
    <actuator name="motor3">
      <hardwareInterface>hardware_interface/PositionJointInterface</hardwareInterface>
      <mechanicalReduction>1</mechanicalReduction>
    </actuator>
  </transmission>

  <transmission name="tran4">
    <type>transmission_interface/SimpleTransmission</type>
    <joint name="joint4">
      <hardwareInterface>hardware_interface/PositionJointInterface</hardwareInterface>
    </joint>
    <actuator name="motor4">
      <hardwareInterface>hardware_interface/PositionJointInterface</hardwareInterface>
      <mechanicalReduction>1</mechanicalReduction>
    </actuator>
  </transmission>

  <transmission name="tran5">
    <type>transmission_interface/SimpleTransmission</type>
    <joint name="joint5">
      <hardwareInterface>hardware_interface/PositionJointInterface</hardwareInterface>
    </joint>
    <actuator name="motor5">
      <hardwareInterface>hardware_interface/PositionJointInterface</hardwareInterface>
      <mechanicalReduction>1</mechanicalReduction>
    </actuator>
  </transmission>

  <!-- Add gazebo-specific joint controller configs to mimic SDF PID values -->
  <gazebo>
    <plugin name="gazebo_ros_control" filename="libgazebo_ros_control.so">
      <robotNamespace>/five_dof_arm</robotNamespace>
      <robotParam>robot_description</robotParam>
      <controlPeriod>0.001</controlPeriod>
    </plugin>
  </gazebo>

  <gazebo>
    <plugin name="joint_state_publisher" filename="libgazebo_ros_joint_state_publisher.so">
      <jointName>joint1, joint2, joint3, joint4, joint5</jointName>
      <robotNamespace>/five_dof_arm</robotNamespace>
    </plugin>
  </gazebo>

  <!-- Controller tuning to match SDF -->
  <gazebo>
    <plugin name="joint1_position_controller" filename="libgazebo_ros_control.so">
      <robotNamespace>/five_dof_arm</robotNamespace>
      <pid_gains>
        <joint name="joint1">
          <p>500.0</p>
          <i>5.0</i>
          <d>20.0</d>
        </joint>
      </pid_gains>
    </plugin>
  </gazebo>

  <gazebo>
    <plugin name="joint2_position_controller" filename="libgazebo_ros_control.so">
      <robotNamespace>/five_dof_arm</robotNamespace>
      <pid_gains>
        <joint name="joint2">
          <p>700.0</p>
          <i>5.0</i>
          <d>20.0</d>
        </joint>
      </pid_gains>
    </plugin>
  </gazebo>

  <gazebo>
    <plugin name="joint3_position_controller" filename="libgazebo_ros_control.so">
      <robotNamespace>/five_dof_arm</robotNamespace>
      <pid_gains>
        <joint name="joint3">
          <p>600.0</p>
          <i>5.0</i>
          <d>20.0</d>
        </joint>
      </pid_gains>
    </plugin>
  </gazebo>

  <gazebo>
    <plugin name="joint4_position_controller" filename="libgazebo_ros_control.so">
      <robotNamespace>/five_dof_arm</robotNamespace>
      <pid_gains>
        <joint name="joint4">
          <p>500.0</p>
          <i>5.0</i>
          <d>20.0</d>
        </joint>
      </pid_gains>
    </plugin>
  </gazebo>

  <gazebo>
    <plugin name="joint5_position_controller" filename="libgazebo_ros_control.so">
      <robotNamespace>/five_dof_arm</robotNamespace>
      <pid_gains>
        <joint name="joint5">
          <p>200.0</p>
          <i>1.0</i>
          <d>40.0</d>
        </joint>
      </pid_gains>
    </plugin>
  </gazebo>
</robot>